[2025-04-16T13:34:32.774+0000] {taskinstance.py:1956} INFO - Dependencies all met for dep_context=non-requeueable deps ti=<TaskInstance: Stock_info_Proj.Spark_Processing scheduled__2025-04-16T12:40:00+00:00 [queued]>
[2025-04-16T13:34:32.781+0000] {taskinstance.py:1956} INFO - Dependencies all met for dep_context=requeueable deps ti=<TaskInstance: Stock_info_Proj.Spark_Processing scheduled__2025-04-16T12:40:00+00:00 [queued]>
[2025-04-16T13:34:32.782+0000] {taskinstance.py:2170} INFO - Starting attempt 1 of 3
[2025-04-16T13:34:32.792+0000] {taskinstance.py:2191} INFO - Executing <Task(PythonOperator): Spark_Processing> on 2025-04-16 12:40:00+00:00
[2025-04-16T13:34:32.796+0000] {standard_task_runner.py:60} INFO - Started process 8752 to run task
[2025-04-16T13:34:32.799+0000] {standard_task_runner.py:87} INFO - Running: ['***', 'tasks', 'run', 'Stock_info_Proj', 'Spark_Processing', 'scheduled__2025-04-16T12:40:00+00:00', '--job-id', '18', '--raw', '--subdir', 'DAGS_FOLDER/Project_tasks2.py', '--cfg-path', '/tmp/tmp53_2yks1']
[2025-04-16T13:34:32.800+0000] {standard_task_runner.py:88} INFO - Job 18: Subtask Spark_Processing
[2025-04-16T13:34:32.840+0000] {task_command.py:423} INFO - Running <TaskInstance: Stock_info_Proj.Spark_Processing scheduled__2025-04-16T12:40:00+00:00 [running]> on host af2bad3d929d
[2025-04-16T13:34:32.903+0000] {taskinstance.py:2480} INFO - Exporting env vars: AIRFLOW_CTX_DAG_OWNER='***' AIRFLOW_CTX_DAG_ID='Stock_info_Proj' AIRFLOW_CTX_TASK_ID='Spark_Processing' AIRFLOW_CTX_EXECUTION_DATE='2025-04-16T12:40:00+00:00' AIRFLOW_CTX_TRY_NUMBER='1' AIRFLOW_CTX_DAG_RUN_ID='scheduled__2025-04-16T12:40:00+00:00'
[2025-04-16T13:34:32.904+0000] {taskinstance.py:2698} ERROR - Task failed with exception
Traceback (most recent call last):
  File "/home/airflow/.local/lib/python3.10/site-packages/airflow/models/taskinstance.py", line 433, in _execute_task
    result = execute_callable(context=context, **execute_callable_kwargs)
  File "/home/airflow/.local/lib/python3.10/site-packages/airflow/operators/python.py", line 199, in execute
    return_value = self.execute_callable()
  File "/home/airflow/.local/lib/python3.10/site-packages/airflow/operators/python.py", line 216, in execute_callable
    return self.python_callable(*self.op_args, **self.op_kwargs)
TypeError: process_data() missing 2 required positional arguments: 'time_processing' and 'company'
[2025-04-16T13:34:32.910+0000] {taskinstance.py:1138} INFO - Marking task as FAILED. dag_id=Stock_info_Proj, task_id=Spark_Processing, execution_date=20250416T124000, start_date=20250416T133432, end_date=20250416T133432
[2025-04-16T13:34:32.919+0000] {standard_task_runner.py:107} ERROR - Failed to execute job 18 for task Spark_Processing (process_data() missing 2 required positional arguments: 'time_processing' and 'company'; 8752)
[2025-04-16T13:34:32.931+0000] {local_task_job_runner.py:234} INFO - Task exited with return code 1
[2025-04-16T13:34:32.946+0000] {taskinstance.py:3280} INFO - 0 downstream tasks scheduled from follow-on schedule check
